Workbook

Sheet Assumptions
A1: GeneralLink Turnkey Outsourcing — Costing Assumptions (all figures in MYR)
A2: Edit any blue figure below — every other tab recalculates from these inputs.
A4: Statutory On-Costs (Employer Side)
A5: Assumption | B5: Value | C5: Source / Note
A6: EPF employer rate — wages ≤ RM5,000/month | B6: 0.13 | C6: KWSP statutory rate 2026 (ajobthing.com, swingvy.com)
A7: EPF employer rate — wages > RM5,000/month | B7: 0.12 | C7: KWSP statutory rate 2026
A8: SOCSO employer rate | B8: 0.0175 | C8: PERKESO 2026, capped at wage ceiling below
A9: SOCSO monthly wage ceiling (RM) | B9: 6000 | C9: PERKESO 2026 ceiling
A10: EIS employer rate | B10: 0.002 | C10: SOCSO EIS 2026, capped at wage ceiling below
A11: EIS monthly wage ceiling (RM) | B11: 6000 | C11: SOCSO EIS 2026 ceiling
A12: Annual bonus provision (months of salary) | B12: 1 | C12: Assumption — standard 1-month contractual bonus. Adjust to your policy.
A13: Group medical/hospitalisation insurance (RM/employee/year) | B13: 1000 | C13: Estimate — Malaysia SME group H&S plans typically RM600-1,500/pax/yr. Get a broker quote (Allianz/AIA SME plans) to firm this up.
A15: Office
A16: Assumption | B16: Value | C16: Source / Note
A17: Monthly office rent — small private/serviced office, Klang Valley (RM) | B17: 2500 | C17: Estimate — serviced offices RM415-780/pax/mo, traditional ~RM3-5 psf (klofficeshoplotfactory.com, sandboxco.space)
A18: Rent deposit (months, paid once at setup) | B18: 3 | C18: Standard Malaysia commercial lease practice (2 deposit + 1 advance)
A19: Monthly utilities & internet (RM) | B19: 600 | C19: Estimate for a 4-6 pax small office
A21: Hosting & Infrastructure Scaling
A22: Assumption | B22: Value | C22: Source / Note
A23: Base VPS hosting — covers up to 1 scaling tier of users (RM/month) | B23: 113 | C23: DigitalOcean 4GB/2vCPU Droplet, Singapore DC — quoted 14 Aug 2026 (digitalocean.com/pricing/droplets)
A24: Hosting step-up per additional user tier (RM/month) | B24: 150 | C24: Estimate — next VPS size tier (8GB/16GB) as user base grows
A25: Domain renewal, .my (RM/year) | B25: 80 | C25: Typical .my domain renewal rate
A26: SSL certificate (RM/year) | B26: 0 | C26: Let's Encrypt — free, auto-renewing. No cost unless a paid EV/OV cert is wanted later.
A27: Database engine licence | B27: 0 | C27: MySQL Community Edition — free & open-source. No licence fee at any scale.
A29: AI Assistant & Communication APIs (usage-based — scale with users)
A30: Assumption | B30: Value | C30: Source / Note
A31: Claude AI (Carolyn assistant) — avg tokens per interaction | B31: 2000 | C31: Estimate — a typical write-assist/chat exchange. Adjust as usage data comes in.
A32: Claude AI blended rate (RM per 1,000,000 tokens) | B32: 28 | C32: Claude Sonnet 5: US$2/$10 per M in/out tokens through 31 Aug 2026, blended ~US$6/M × ~4.7 MYR (anthropic.com, cloudzero.com)
A33: AI interactions per user per month | B33: 2 | C33: Estimate — onboarding help, message drafting, etc.
A34: ElevenLabs voice API (RM/month, starting tier) | B34: 100 | C34: Estimate — entry tier; upgrade as voice feature usage grows
A35: WhatsApp Business API — BSP platform fee (RM/month) | B35: 300 | C35: Typical BSP fee range RM150-1,200/mo (whautomate.com, forwardchat.my)
A36: WhatsApp utility/notification message rate (RM/message) | B36: 0.06 | C36: Meta 2026 Malaysia utility message rate ~RM0.0564 (go4whatsup.com)
A37: WhatsApp messages per user per month | B37: 1 | C37: Estimate — 1 notification per active user per month
A38: Google Workspace (RM/user/month, professional email) | B38: 25 | C38: Google Workspace Business Starter, per staff mailbox
A39: Accounting/bookkeeping software (RM/month) | B39: 100 | C39: Estimate — SQL Account / AutoCount entry tier
A41: Scaling Tiers & Support Ratio
A42: Assumption | B42: Value | C42: Source / Note
A43: Users per scaling tier | B43: 10000 | C43: Per Chris's brief: cost scales in blocks of 10,000 users
A44: Support/ops headcount needed per additional tier | B44: 1 | C44: Estimate — 1 support staff per ~10,000 active users
A45: Starting assumed monthly platform sales volume (RM) | B45: 10000 | C45: Per Chris's brief — actual customer sales volume unknown, use RM10,000/month as the opening benchmark
...

Sheet GroundZeroSetup
A1: Ground-Zero Setup — One-Time Costs (Month 0)
A3: Item | B3: Qty | C3: Unit Cost (RM) | D3: Total (RM) | E3: Notes
A4: Office rental deposit (2 deposit + 1 advance) | B4: - | C4: - | D4: =Assumptions!$B$17*Assumptions!$B$18 -> 7500 | E4: Linked to Assumptions: monthly rent x deposit months
A5: Minor office renovation / signage | B5: 1 | C5: 2000 | D5: =B5*C5 -> 2000 | E5: Paint, signage, basic partition — estimate
A6: Office furniture — desks, chairs, cabinet (4 pax) | B6: 4 | C6: 1500 | D6: =B6*C6 -> 6000 | E6: Estimate, RM1,500/workstation set
A7: Business laptops | B7: 4 | C7: 3500 | D7: =B7*C7 -> 14000 | E7: Mid-spec business laptop, Malaysia retail estimate
A8: All-in-one printer/scanner | B8: 1 | C8: 1200 | D8: =B8*C8 -> 1200 | E8: Laser AIO printer, Malaysia retail estimate
A9: Company mobile device (ops/QA testing phone) | B9: 1 | C9: 1200 | D9: =B9*C9 -> 1200 | E9: Mid-range Android/iOS test device
A10: Network setup — router, switch, cabling | B10: 1 | C10: 500 | D10: =B10*C10 -> 500 | E10: Estimate
A11: IT security setup — antivirus, firewall, backup tooling (Yr1 licence) | B11: 1 | C11: 800 | D11: =B11*C11 -> 800 | E11: Estimate, annual licence bundle
A12: Company registration — SSM Sdn Bhd incorporation | B12: 1 | C12: 1500 | D12: =B12*C12 -> 1500 | E12: One-time incorporation fee, if not already registered
A13: Legal — service agreement, SLA & data-protection agreement drafting | B13: 1 | C13: 3000 | D13: =B13*C13 -> 3000 | E13: Recommended given customer data/PDPA exposure — get a lawyer to draft/review
A14: Domain registration — Year 1 | B14: - | C14: - | D14: =Assumptions!$B$25 -> 80 | E14: Linked to Assumptions: .my domain, Year 1
A15: TOTAL GROUND-ZERO SETUP (ONE-TIME) | D15: =SUM(D4:D14) -> 37780

Sheet TeamPayroll
A1: Team & Payroll — Headcount and Fully-Loaded Employer Cost
A2: Fully-loaded cost = monthly salary x12 + EPF + SOCSO + EIS + bonus provision + medical insurance (rates from Assumptions tab).
A4: Role | B4: Year 1 HC | C4: Year 2 HC | D4: Year 3 HC | E4: Monthly Salary/head (RM) | F4: Year 1 Fully-Loaded Cost (RM) | G4: Year 2 Fully-Loaded Cost (RM) | H4: Year 3 Fully-Loaded Cost (RM)
A5: Project Lead / Founder | B5: 1 | C5: 1 | D5: 1 | E5: 10000 | F5: =B5*($E5*12+$E5*12*IF($E5<=5000,Assumptions!$B$6,Assumptions!$B$7)+MIN($E5,Assumptions!$B$9)*Assumptions!$B$8*12+MIN($E5,Assumptions!$B$11)*Assumptions!$B$10*12+$E5*Assumptions!$B$12+Assumptions!$B$13) -> 146804 | G5: =C5*($E5*12+$E5*12*IF($E5<=5000,Assumptions!$B$6,Assumptions!$B$7)+MIN($E5,Assumptions!$B$9)*Assumptions!$B$8*12+MIN($E5,Assumptions!$B$11)*Assumptions!$B$10*12+$E5*Assumptions!$B$12+Assumptions!$B$13) -> 146804 | H5: =D5*($E5*12+$E5*12*IF($E5<=5000,Assumptions!$B$6,Assumptions!$B$7)+MIN($E5,Assumptions!$B$9)*Assumptions!$B$8*12+MIN($E5,Assumptions!$B$11)*Assumptions!$B$10*12+$E5*Assumptions!$B$12+Assumptions!$B$13) -> 146804
A6: Full-Stack Developer (Laravel/PHP) — maintenance & enhancements | B6: 1 | C6: 2 | D6: 3 | E6: 6500 | F6: =B6*($E6*12+$E6*12*IF($E6<=5000,Assumptions!$B$6,Assumptions!$B$7)+MIN($E6,Assumptions!$B$9)*Assumptions!$B$8*12+MIN($E6,Assumptions!$B$11)*Assumptions!$B$10*12+$E6*Assumptions!$B$12+Assumptions!$B$13) -> 96264 | G6: =C6*($E6*12+$E6*12*IF($E6<=5000,Assumptions!$B$6,Assumptions!$B$7)+MIN($E6,Assumptions!$B$9)*Assumptions!$B$8*12+MIN($E6,Assumptions!$B$11)*Assumptions!$B$10*12+$E6*Assumptions!$B$12+Assumptions!$B$13) -> 192528 | H6: =D6*($E6*12+$E6*12*IF($E6<=5000,Assumptions!$B$6,Assumptions!$B$7)+MIN($E6,Assumptions!$B$9)*Assumptions!$B$8*12+MIN($E6,Assumptions!$B$11)*Assumptions!$B$10*12+$E6*Assumptions!$B$12+Assumptions!$B$13) -> 288792
A7: Customer Support & Vendor/Agent Relations Officer | B7: 1 | C7: 2 | D7: 3 | E7: 3000 | F7: =B7*($E7*12+$E7*12*IF($E7<=5000,Assumptions!$B$6,Assumptions!$B$7)+MIN($E7,Assumptions!$B$9)*Assumptions!$B$8*12+MIN($E7,Assumptions!$B$11)*Assumptions!$B$10*12+$E7*Assumptions!$B$12+Assumptions!$B$13) -> 45382 | G7: =C7*($E7*12+$E7*12*IF($E7<=5000,Assumptions!$B$6,Assumptions!$B$7)+MIN($E7,Assumptions!$B$9)*Assumptions!$B$8*12+MIN($E7,Assumptions!$B$11)*Assumptions!$B$10*12+$E7*Assumptions!$B$12+Assumptions!$B$13) -> 90764 | H7: =D7*($E7*12+$E7*12*IF($E7<=5000,Assumptions!$B$6,Assumptions!$B$7)+MIN($E7,Assumptions!$B$9)*Assumptions!$B$8*12+MIN($E7,Assumptions!$B$11)*Assumptions!$B$10*12+$E7*Assumptions!$B$12+Assumptions!$B$13) -> 136146
A8: Admin / Finance Executive | B8: 0.5 | C8: 1 | D8: 1 | E8: 3600 | F8: =B8*($E8*12+$E8*12*IF($E8<=5000,Assumptions!$B$6,Assumptions!$B$7)+MIN($E8,Assumptions!$B$9)*Assumptions!$B$8*12+MIN($E8,Assumptions!$B$11)*Assumptions!$B$10*12+$E8*Assumptions!$B$12+Assumptions!$B$13) -> 27129.2 | G8: =C8*($E8*12+$E8*12*IF($E8<=5000,Assumptions!$B$6,Assumptions!$B$7)+MIN($E8,Assumptions!$B$9)*Assumptions!$B$8*12+MIN($E8,Assumptions!$B$11)*Assumptions!$B$10*12+$E8*Assumptions!$B$12+Assumptions!$B$13) -> 54258.4 | H8: =D8*($E8*12+$E8*12*IF($E8<=5000,Assumptions!$B$6,Assumptions!$B$7)+MIN($E8,Assumptions!$B$9)*Assumptions!$B$8*12+MIN($E8,Assumptions!$B$11)*Assumptions!$B$10*12+$E8*Assumptions!$B$12+Assumptions!$B$13) -> 54258.4
A9: DevOps / Security Consultant (retainer basis) | B9: 0 | C9: 0.25 | D9: 0.5 | E9: 5000 | F9: =B9*($E9*12+$E9*12*IF($E9<=5000,Assumptions!$B$6,Assumptions!$B$7)+MIN($E9,Assumptions!$B$9)*Assumptions!$B$8*12+MIN($E9,Assumptions!$B$11)*Assumptions!$B$10*12+$E9*Assumptions!$B$12+Assumptions!$B$13) -> 0 | G9: =C9*($E9*12+$E9*12*IF($E9<=5000,Assumptions!$B$6,Assumptions!$B$7)+MIN($E9,Assumptions!$B$9)*Assumptions!$B$8*12+MIN($E9,Assumptions!$B$11)*Assumptions!$B$10*12+$E9*Assumptions!$B$12+Assumptions!$B$13) -> 18742.5 | H9: =D9*($E9*12+$E9*12*IF($E9<=5000,Assumptions!$B$6,Assumptions!$B$7)+MIN($E9,Assumptions!$B$9)*Assumptions!$B$8*12+MIN($E9,Assumptions!$B$11)*Assumptions!$B$10*12+$E9*Assumptions!$B$12+Assumptions!$B$13) -> 37485
A10: TOTAL HEADCOUNT | B10: =SUM(B5:B9) -> 3.5 | C10: =SUM(C5:C9) -> 6.25 | D10: =SUM(D5:D9) -> 8.5
A11: TOTAL PAYROLL COST (fully-loaded) | F11: =SUM(F5:F9) -> 315579.2 | G11: =SUM(G5:G9) -> 503096.9 | H11: =SUM(H5:H9) -> 663485.4
A13: Note: Malaysia Employment Act annual leave (8-16 days depending on tenure) and public holidays are paid leave already funded within the monthly salary above — not a separate cost line.
A14: Headcount grows with the user base — see the Scaling Model tab for the ratio used (1 support/ops hire per additional 10,000 active users) and adjust Year 2/3 HC above to match your actual sales pipeline.

Sheet HostingAPIs
A1: Hosting, Subscriptions & APIs — Monthly Recurring Cost by Year
A2: Scales automatically with the estimated active-user figures on the Assumptions tab.
A4: Item (monthly) | B4: Year 1 (RM/mo) | C4: Year 2 (RM/mo) | D4: Year 3 (RM/mo) | E4: Notes
A5: VPS hosting (steps up per 10,000-user tier) | B5: =Assumptions!$B$23+MAX(0,ROUNDUP(Assumptions!$B$46/Assumptions!$B$43,0)-1)*Assumptions!$B$24 -> 113 | C5: =Assumptions!$B$23+MAX(0,ROUNDUP(Assumptions!$B$47/Assumptions!$B$43,0)-1)*Assumptions!$B$24 -> 263 | D5: =Assumptions!$B$23+MAX(0,ROUNDUP(Assumptions!$B$48/Assumptions!$B$43,0)-1)*Assumptions!$B$24 -> 563 | E5: DigitalOcean 4GB Droplet base + step-up per additional user tier
A6: Domain + SSL (annualised) | B6: =(Assumptions!$B$25+Assumptions!$B$26)/12 -> 6.6666667 | C6: =(Assumptions!$B$25+Assumptions!$B$26)/12 -> 6.6666667 | D6: =(Assumptions!$B$25+Assumptions!$B$26)/12 -> 6.6666667 | E6: Domain renewal only — SSL is free (Let's Encrypt)
A7: Claude AI assistant (Carolyn) — usage-based | B7: =Assumptions!$B$46*Assumptions!$B$33*Assumptions!$B$31/1000000*Assumptions!$B$32 -> 280 | C7: =Assumptions!$B$47*Assumptions!$B$33*Assumptions!$B$31/1000000*Assumptions!$B$32 -> 1680 | D7: =Assumptions!$B$48*Assumptions!$B$33*Assumptions!$B$31/1000000*Assumptions!$B$32 -> 3920 | E7: Users x interactions/user x tokens/interaction, at blended Claude rate
A8: ElevenLabs voice API | B8: =Assumptions!$B$34 -> 100 | C8: =Assumptions!$B$34 -> 100 | D8: =Assumptions!$B$34 -> 100 | E8: Flat starting-tier estimate — review/upgrade as voice usage grows
A9: WhatsApp Business API (BSP + messages) | B9: =Assumptions!$B$35+Assumptions!$B$46*Assumptions!$B$37*Assumptions!$B$36 -> 450 | C9: =Assumptions!$B$35+Assumptions!$B$47*Assumptions!$B$37*Assumptions!$B$36 -> 1200 | D9: =Assumptions!$B$35+Assumptions!$B$48*Assumptions!$B$37*Assumptions!$B$36 -> 2400 | E9: BSP platform fee + per-user notification volume
A10: Google Workspace (professional email, per staff) | B10: =TeamPayroll!B$10*Assumptions!$B$38 -> 87.5 | C10: =TeamPayroll!C$10*Assumptions!$B$38 -> 156.25 | D10: =TeamPayroll!D$10*Assumptions!$B$38 -> 212.5 | E10: Linked to Team & Payroll headcount total for that year
A11: Accounting / bookkeeping software | B11: =Assumptions!$B$39 -> 100 | C11: =Assumptions!$B$39 -> 100 | D11: =Assumptions!$B$39 -> 100 | E11: Flat monthly estimate
A12: MySQL database engine | B12: =Assumptions!$B$27 -> 0 | C12: =Assumptions!$B$27 -> 0 | D12: =Assumptions!$B$27 -> 0 | E12: Community Edition — RM0, no licence fee at any scale
A13: TOTAL MONTHLY RECURRING (technical) | B13: =SUM(B5:B12) -> 1137.1667 | C13: =SUM(C5:C12) -> 3505.9167 | D13: =SUM(D5:D12) -> 7302.1667
A14: TOTAL ANNUAL (technical, x12) | B14: =B13*12 -> 13646 | C14: =C13*12 -> 42071 | D14: =D13*12 -> 87626

Sheet OfficeAdmin
A1: Office & Admin Overheads — Annual Cost by Year
A3: Item (annual) | B3: Year 1 (RM) | C3: Year 2 (RM) | D3: Year 3 (RM) | E3: Notes
A4: Office rent (annualised) | B4: =Assumptions!$B$17*12 -> 30000 | C4: =Assumptions!$B$17*12 -> 30000 | D4: =Assumptions!$B$17*12 -> 30000 | E4: Linked to Assumptions monthly rent. Revisit if team outgrows the space by Year 3.
A5: Utilities & internet (annualised) | B5: =Assumptions!$B$19*12 -> 7200 | C5: =Assumptions!$B$19*12 -> 7200 | D5: =Assumptions!$B$19*12 -> 7200 | E5: Linked to Assumptions
A6: Company secretary retainer (statutory, Sdn Bhd) | B6: 1200 | C6: 1200 | D6: 1200 | E6: SSM-mandated company secretary, typical small-company retainer
A7: Bookkeeping, tax filing & annual audit-exemption service | B7: 2500 | C7: 2500 | D7: 2500 | E7: Outsourced accountant/tax agent package
A8: Professional indemnity / cyber liability insurance | B8: 4000 | C8: 4000 | D8: 4000 | E8: Recommended — platform handles customer & vendor personal/financial data
A9: General business insurance (equipment, fire, burglary) | B9: 1200 | C9: 1200 | D9: 1200 | E9: Covers office equipment and premises
A10: TOTAL OFFICE & ADMIN OVERHEAD (annual) | B10: =SUM(B4:B9) -> 46100 | C10: =SUM(C4:C9) -> 46100 | D10: =SUM(D4:D9) -> 46100

Sheet ScalingModel
A1: Scaling Model — Cost to Serve, by User Tier (blocks of 10,000 users)
A2: Illustrates unlimited-user capacity: every additional 10,000 users adds a predictable, transparent slice of cost.
A4: Users | B4: Hosting (RM/mo) | C4: AI Assistant (RM/mo) | D4: WhatsApp (RM/mo) | E4: Support HC | F4: Support Payroll (RM/mo) | G4: TOTAL Cost to Serve (RM/mo) | H4: Cost / User (RM)
A5: 1000 | B5: =Assumptions!$B$23+MAX(0,ROUNDUP(A5/Assumptions!$B$43,0)-1)*Assumptions!$B$24 -> 113 | C5: =A5*Assumptions!$B$33*Assumptions!$B$31/1000000*Assumptions!$B$32 -> 112 | D5: =Assumptions!$B$35+A5*Assumptions!$B$37*Assumptions!$B$36 -> 360 | E5: =ROUNDUP(A5/Assumptions!$B$43,0)*Assumptions!$B$44 -> 1 | F5: =E5*((TeamPayroll!$E$7*12+TeamPayroll!$E$7*12*IF(TeamPayroll!$E$7<=5000,Assumptions!$B$6,Assumptions!$B$7)+MIN(TeamPayroll!$E$7,Assumptions!$B$9)*Assumptions!$B$8*12+MIN(TeamPayroll!$E$7,Assumptions!$B$11)*Assumptions!$B$10*12+TeamPayroll!$E$7*Assumptions!$B$12+Assumptions!$B$13)/12) -> 3781.8333 | G5: =SUM(B5:D5)+F5 -> 4366.8333 | H5: =G5/A5 -> 4.3668333
A6: 10000 | B6: =Assumptions!$B$23+MAX(0,ROUNDUP(A6/Assumptions!$B$43,0)-1)*Assumptions!$B$24 -> 113 | C6: =A6*Assumptions!$B$33*Assumptions!$B$31/1000000*Assumptions!$B$32 -> 1120 | D6: =Assumptions!$B$35+A6*Assumptions!$B$37*Assumptions!$B$36 -> 900 | E6: =ROUNDUP(A6/Assumptions!$B$43,0)*Assumptions!$B$44 -> 1 | F6: =E6*((TeamPayroll!$E$7*12+TeamPayroll!$E$7*12*IF(TeamPayroll!$E$7<=5000,Assumptions!$B$6,Assumptions!$B$7)+MIN(TeamPayroll!$E$7,Assumptions!$B$9)*Assumptions!$B$8*12+MIN(TeamPayroll!$E$7,Assumptions!$B$11)*Assumptions!$B$10*12+TeamPayroll!$E$7*Assumptions!$B$12+Assumptions!$B$13)/12) -> 3781.8333 | G6: =SUM(B6:D6)+F6 -> 5914.8333 | H6: =G6/A6 -> 0.59148333
A7: 20000 | B7: =Assumptions!$B$23+MAX(0,ROUNDUP(A7/Assumptions!$B$43,0)-1)*Assumptions!$B$24 -> 263 | C7: =A7*Assumptions!$B$33*Assumptions!$B$31/1000000*Assumptions!$B$32 -> 2240 | D7: =Assumptions!$B$35+A7*Assumptions!$B$37*Assumptions!$B$36 -> 1500 | E7: =ROUNDUP(A7/Assumptions!$B$43,0)*Assumptions!$B$44 -> 2 | F7: =E7*((TeamPayroll!$E$7*12+TeamPayroll!$E$7*12*IF(TeamPayroll!$E$7<=5000,Assumptions!$B$6,Assumptions!$B$7)+MIN(TeamPayroll!$E$7,Assumptions!$B$9)*Assumptions!$B$8*12+MIN(TeamPayroll!$E$7,Assumptions!$B$11)*Assumptions!$B$10*12+TeamPayroll!$E$7*Assumptions!$B$12+Assumptions!$B$13)/12) -> 7563.6667 | G7: =SUM(B7:D7)+F7 -> 11566.667 | H7: =G7/A7 -> 0.57833333
A8: 30000 | B8: =Assumptions!$B$23+MAX(0,ROUNDUP(A8/Assumptions!$B$43,0)-1)*Assumptions!$B$24 -> 413 | C8: =A8*Assumptions!$B$33*Assumptions!$B$31/1000000*Assumptions!$B$32 -> 3360 | D8: =Assumptions!$B$35+A8*Assumptions!$B$37*Assumptions!$B$36 -> 2100 | E8: =ROUNDUP(A8/Assumptions!$B$43,0)*Assumptions!$B$44 -> 3 | F8: =E8*((TeamPayroll!$E$7*12+TeamPayroll!$E$7*12*IF(TeamPayroll!$E$7<=5000,Assumptions!$B$6,Assumptions!$B$7)+MIN(TeamPayroll!$E$7,Assumptions!$B$9)*Assumptions!$B$8*12+MIN(TeamPayroll!$E$7,Assumptions!$B$11)*Assumptions!$B$10*12+TeamPayroll!$E$7*Assumptions!$B$12+Assumptions!$B$13)/12) -> 11345.5 | G8: =SUM(B8:D8)+F8 -> 17218.5 | H8: =G8/A8 -> 0.57395
A9: 50000 | B9: =Assumptions!$B$23+MAX(0,ROUNDUP(A9/Assumptions!$B$43,0)-1)*Assumptions!$B$24 -> 713 | C9: =A9*Assumptions!$B$33*Assumptions!$B$31/1000000*Assumptions!$B$32 -> 5600 | D9: =Assumptions!$B$35+A9*Assumptions!$B$37*Assumptions!$B$36 -> 3300 | E9: =ROUNDUP(A9/Assumptions!$B$43,0)*Assumptions!$B$44 -> 5 | F9: =E9*((TeamPayroll!$E$7*12+TeamPayroll!$E$7*12*IF(TeamPayroll!$E$7<=5000,Assumptions!$B$6,Assumptions!$B$7)+MIN(TeamPayroll!$E$7,Assumptions!$B$9)*Assumptions!$B$8*12+MIN(TeamPayroll!$E$7,Assumptions!$B$11)*Assumptions!$B$10*12+TeamPayroll!$E$7*Assumptions!$B$12+Assumptions!$B$13)/12) -> 18909.167 | G9: =SUM(B9:D9)+F9 -> 28522.167 | H9: =G9/A9 -> 0.57044333
A10: 100000 | B10: =Assumptions!$B$23+MAX(0,ROUNDUP(A10/Assumptions!$B$43,0)-1)*Assumptions!$B$24 -> 1463 | C10: =A10*Assumptions!$B$33*Assumptions!$B$31/1000000*Assumptions!$B$32 -> 11200 | D10: =Assumptions!$B$35+A10*Assumptions!$B$37*Assumptions!$B$36 -> 6300 | E10: =ROUNDUP(A10/Assumptions!$B$43,0)*Assumptions!$B$44 -> 10 | F10: =E10*((TeamPayroll!$E$7*12+TeamPayroll!$E$7*12*IF(TeamPayroll!$E$7<=5000,Assumptions!$B$6,Assumptions!$B$7)+MIN(TeamPayroll!$E$7,Assumptions!$B$9)*Assumptions!$B$8*12+MIN(TeamPayroll!$E$7,Assumptions!$B$11)*Assumptions!$B$10*12+TeamPayroll!$E$7*Assumptions!$B$12+Assumptions!$B$13)/12) -> 37818.333 | G10: =SUM(B10:D10)+F10 -> 56781.333 | H10: =G10/A10 -> 0.56781333
A12: Starting assumed platform sales volume: RM10,000/month (per Chris's brief). Each further RM10,000/month of transaction volume is expected to track roughly with the same 10,000-user support ratio above — revisit once real usage data comes in.

Sheet Summary
A1: 3-Year Cost Summary & Proposed Project Sum
A3: Cost Category | B3: Year 1 (RM) | C3: Year 2 (RM) | D3: Year 3 (RM) | E3: 3-Year Total (RM)
A4: Ground-zero setup (one-time, Year 1 only) | B4: =GroundZeroSetup!$D$15 -> 37780 | C4: 0 | D4: 0 | E4: =SUM(B4:D4) -> 37780
A5: Team & payroll (fully-loaded) | B5: =TeamPayroll!$F$11 -> 315579.2 | C5: =TeamPayroll!$G$11 -> 503096.9 | D5: =TeamPayroll!$H$11 -> 663485.4 | E5: =SUM(B5:D5) -> 1482161.5
A6: Hosting, subscriptions & APIs (annual) | B6: =HostingAPIs!$B$14 -> 13646 | C6: =HostingAPIs!$C$14 -> 42071 | D6: =HostingAPIs!$D$14 -> 87626 | E6: =SUM(B6:D6) -> 143343
A7: Office & admin overheads (annual) | B7: =OfficeAdmin!$B$10 -> 46100 | C7: =OfficeAdmin!$C$10 -> 46100 | D7: =OfficeAdmin!$D$10 -> 46100 | E7: =SUM(B7:D7) -> 138300
A8: TOTAL COST BASE | B8: =SUM(B4:B7) -> 413105.2 | C8: =SUM(C4:C7) -> 591267.9 | D8: =SUM(D4:D7) -> 797211.4 | E8: =SUM(E4:E7) -> 1801584.5
A10: Proposed Commercial Terms
A11: Margin applied (from Assumptions tab) | B11: =Assumptions!$B$52 -> 0.2
A12: PROPOSED PROJECT SUM (by year) | B12: =B8*(1+$B$11) -> 495726.24 | C12: =C8*(1+$B$11) -> 709521.48 | D12: =D8*(1+$B$11) -> 956653.68 | E12: =E8*(1+$B$11) -> 2161901.4
A14: TOTAL 3-YEAR PROPOSED PROJECT SUM | E14: =E12 -> 2161901.4
A16: Suggested Payment / Retainer Schedule
A17: Milestone | B17: Timing | C17: % of Year Sum | D17: Amount (RM)
A18: Year 1 — mobilisation payment | B18: On signing (covers ground-zero setup + Month 1-2 ops) | C18: 0.4 | D18: =$B$12*C18 -> 198290.5
A19: Year 1 — progress payment | B19: Month 6 | C19: 0.3 | D19: =$B$12*C19 -> 148717.87
A20: Year 1 — completion payment | B20: Month 12 | C20: 0.3 | D20: =$B$12*C20 -> 148717.87
A21: Year 2 — monthly retainer | B21: Billed monthly in advance | D21: =$C$12/12 -> 59126.79
A22: Year 3 — monthly retainer | B22: Billed monthly in advance | D22: =$D$12/12 -> 79721.14
A24: Notes & exclusions:
A25: • Figures are a planning-grade estimate built from current (Aug 2026) Malaysia market benchmarks — see Assumptions tab for every rate and its source.
A26: • Excludes: payment gateway/merchant fees (add once a gateway is chosen), paid marketing/advertising spend, statutory corporate income tax, and any custom feature scope beyond the current GeneralLink master spec.
A27: • Hosting and API costs are usage-based formulas — actual spend will track real user/transaction volume, not just the illustrative Year 1-3 ramp assumed here.
A28: • Review and re-quote if actual monthly sales volume materially exceeds the RM10,000/month starting assumption, since support headcount is the main cost driver at scale.
